Workbook

Sheet Trades
A1: # | B1: Signal | C1: Datum | D1: Zeit | E1: Account | F1: Coin | G1: Richtung | H1: Kapital | I1: Einsatz | J1: Hebel | K1: % Kapital | L1: Geh.Einsatz | M1: Entry 1 | N1: Entry 2 | O1: Entry 3 | P1: TP1 | Q1: TP2 | R1: TP3 | S1: SL | T1: Ausstieg Dat. | U1: Ausstieg Zeit | V1: Kurs Ausstieg | W1: Dauer | X1: ROI % | Y1: PNL USDT | Z1: Net PNL | AA1: Abgeschl. | AB1: Notiz
A2: 1 | B2: Viona | C2: 17.02.26 | D2: 08:35:00 | E2: CK_one | F2: BEAM | H2: 100 | I2: 10 | J2: 10 | K2: 10% | L2: 100 | M2: 0,00241 | T2: 17.02.26 | U2: 10:47:00 | W2: 0.091666667 | X2: 18.37 | Y2: 1.85 | AA2: j
A3: 2 | B3: Viona | C3: 20.02.26 | D3: 09:31:00 | E3: CK_one | F3: FF | H3: 150 | I3: 22,5 | J3: 10 | K3: 15% | L3: 225 | M3: 0,0793 | T3: 21.02.26 | U3: 09:07:00 | W3: 0.98333333 | X3: 17.67 | Y3: 2.66 | AA3: j
A4: 3 | B4: Viona | C4: 20.02.26 | D4: 12:29:00 | E4: CC_Master2 | F4: RSR | H4: 100 | I4: 10 | J4: 10 | K4: 10% | L4: 100 | M4: 0,001481 | T4: 21.02.26 | U4: 08:08:00 | W4: 0.81875 | X4: 17.92 | Y4: 1.78 | AA4: j
A5: 4 | B5: Viona | C5: 24.02.26 | D5: 09:10:00 | E5: cc_Master3 | F5: ALGO | H5: 300 | I5: 60 | J5: 10 | K5: 20% | L5: 600 | M5: 0,0837 | T5: 24.02.26 | U5: 21:20:00 | W5: 0.50694444 | X5: 13.89 | Y5: 8.67 | AA5: j
A6: 5 | B6: Viona | C6: 24.02.26 | D6: 12:05:00 | E6: cc_Master4 | F6: ALT | H6: 500 | I6: 50 | J6: 10 | K6: 10% | L6: 500 | M6: 0,00738 | T6: 24.02.26 | U6: 21:19:00 | W6: 0.38472222 | X6: 19.21 | Y6: 9.5 | AA6: j
A7: 6 | B7: Viona | C7: 26.02.26 | D7: 08:14:00 | E7: cc_Master3 | F7: SUI | H7: 300 | I7: 30 | J7: 9 | K7: 10% | L7: 270 | M7: 0,9404 | T7: 27.02.26 | U7: 20:01:00 | W7: 1.4583333 | X7: 11.08 | Y7: 9.54 | AA7: j
A8: 7 | B8: Viona | C8: 26.02.26 | D8: 14:10:00 | E8: cc_Master4 | F8: CAKE | H8: 500 | I8: 75 | J8: 10 | K8: 15% | L8: 750 | M8: 1,2801 | T8: 27.02.26 | U8: 19:54:00 | W8: 1.2083333 | X8: 7.24 | Y8: 13.29 | AA8: j
A9: 8 | B9: Viona | C9: 02.03.26 | D9: 06:15:00 | E9: cc_Master3 | F9: AGLD | H9: 320 | I9: 48 | J9: 9 | K9: 15% | L9: 432 | M9: 0,2208 | T9: 02.03.26 | U9: 07:45:00 | W9: 0.0625 | X9: 16.8 | Y9: 7.98 | AA9: j
A10: 9 | B10: Viona | C10: 03.03.26 | D10: 08:12:00 | E10: CC_Master3 | F10: ENA | H10: 328 | I10: 82 | J10: 10 | K10: 25% | L10: 820 | M10: 0,1092 | T10: 03.03.26 | U10: 12:45:00 | W10: 0.18958333 | X10: 2.22 | Y10: 5.49 | AA10: j
A11: 10 | B11: CryptoCult | C11: 03.03.26 | D11: 08:15:00 | E11: CC_Master4 | F11: XLM | H11: 520 | I11: 130 | J11: 25 | K11: 25% | L11: 3250 | M11: 0,15105 | T11: 03.03.26 | U11: 14:03:00 | W11: 0.24166667 | X11: 22.36 | Y11: 46.85 | AA11: j
A12: 11 | B12: Global Crypto Research | C12: 05.03.26 | D12: 08:05:00 | E12: cc_Master3 | F12: AGLD | G12: l | H12: 250 | I12: 50 | J12: 20 | K12: 20% | L12: 1000 | M12: 0,2543 | T12: 05.03.26 | U12: 20:07:00 | W12: 0.50138889 | X12: 35.15 | Y12: 15.94 | AA12: j
A13: 12 | B13: Global Crypto Research | C13: 04.03.26 | D13: 21:08:00 | E13: cc_Master3 | F13: WET | H13: 328 | I13: 98,4 | J13: 25 | K13: 30% | L13: 2460 | M13: 0,11659 | T13: 03.03.26 | U13: 21:10:00 | X13: -7.4 | Y13: -9.55 | AA13: j
A14: 13 | B14: Global Crypto Research | C14: 04.03.26 | D14: 21:13:00 | E14: cc_Master3 | F14: WET | H14: 320 | I14: 96 | J14: 25 | K14: 30% | L14: 2400 | M14: 0,11745 | T14: 03.03.26 | U14: 21:46:00 | X14: -28.3 | Y14: -35.62 | AA14: j
A15: 14 | B15: CryptoCult | C15: 04.03.26 | D15: 22:06:00 | E15: cc_Master3 | F15: PHA | H15: 290 | I15: 72,5 | J15: 25 | K15: 25% | L15: 1812,5 | M15: 0,04916 | T15: 05.03.25 | U15: 02:22:00 | X15: -50.75 | Y15: -92.52 | AA15: j
A16: 15 | B16: Viona | C16: 05.03.26 | D16: 14:07:00 | E16: cc_Master4 | F16: LINK | G16: s | H16: 520 | I16: 52 | J16: 10 | K16: 10% | L16: 520 | M16: 9,076 | T16: 06.03.25 | U16: 23:13:00 | X16: 40.72 | Y16: 70.1 | AA16: j
A17: 16 | B17: Crypto pro Traders | C17: 07.03.26 | D17: 08:40:00 | E17: CC_Master2 | F17: TRUMP | G17: s | H17: 206 | I17: 10,3 | J17: 50 | K17: 5% | L17: 515 | M17: 3,054 | T17: 07.03.26 | U17: 13:21:00 | W17: 0.19513889 | X17: 6.66 | Y17: -0.12 | AA17: j
A18: 17 | B18: Crypto pro Traders | C18: 07.03.26 | D18: 09:00:00 | E18: CC_Master2 | F18: ALLO | G18: s | H18: 195 | I18: 10,725 | J18: 20 | K18: 6% | L18: 214,5 | M18: 0,1215 | T18: 07.03.26 | U18: 11:32:00 | W18: 0.10555556 | X18: -101.13 | Y18: -10.42 | AA18: j
A19: 18 | B19: Binance 360 | C19: 07.03.26 | D19: 10:10:00 | E19: CC_Master2 | F19: RLC | H19: 184 | I19: 92 | J19: 10 | K19: 50% | L19: 920 | M19: nicht getradet | AA19: j
A20: 19 | B20: Viona | C20: 11.03.26 | D20: 05:43:00 | E20: CC_Master1 | F20: SUI | G20: s | H20: 1000 | I20: 150 | J20: 10 | K20: 15% | L20: 1500 | M20: 0,9498 | T20: 11.03.26 | U20: 22:35:00 | W20: 0.70277778 | X20: 7.88 | Y20: 77.97 | AA20: j
A21: 20 | B21: Viona | C21: 10.03.26 | D21: 15:17:00 | E21: CC_Master4 | F21: LINK | G21: s | H21: 595 | I21: 59,5 | J21: 10 | K21: 10% | L21: 595 | M21: 8,97 | T21: 11.03.26 | U21: 12:40:00 | W21: 0.89097222 | X21: 1.98 | Y21: 5.5 | AA21: j
A22: 21 | B22: Crypto pro Traders | C22: 11.03.26 | D22: 19:18:00 | E22: CC_Master2 | F22: DEGO | G22: s | H22: 206 | I22: 72,1 | J22: 20 | K22: 35% | L22: 1442 | M22: 0,9109 | T22: 11.03.26 | U22: 21:38:00 | W22: 0.097222222 | X22: -96.37 | Y22: -79.83 | AA22: j
A23: 22 | B23: Viona | C23: 11.03.26 | D23: 20:00:00 | E23: cc_Master4 | F23: AVAX | G23: s | H23: 597 | I23: 119,4 | J23: 10 | K23: 20% | L23: 1194 | M23: 9,543 | T23: 11.03.26 | U23: 23:33:00 | W23: 0.14791667 | X23: 6.14 | Y23: 4.8 | AA23: j
A24: 23 | B24: Viona | C24: 13.03.26 | D24: 16:05:00 | E24: CC_Master1 | F24: BCH | I24: 0 | L24: 0 | M24: 461,87 | T24: 14.03.26 | U24: 03:34:00 | W24: 0.47847222 | X24: 1.37 | Y24: 1.46 | AA24: j
A25: 24 | B25: Viona | C25: 16.03.26 | D25: 10:04:00 | E25: CC_Master1 | F25: CELO | I25: 0 | L25: 0 | M25: 0,08 | T25: 17.03.26 | U25: 00:13:00 | W25: 0.58958333 | X25: -14.59 | Y25: -29.04 | AA25: j
A26: 25 | B26: Viona | C26: 18.03.26 | D26: 10:59:00 | E26: CC_Master1 | F26: 1INCH | I26: 0 | L26: 0 | M26: 0,102277 | T26: 18.03.26 | U26: 11:37:00 | W26: 0.026388889 | X26: 10.8 | Y26: 10.64 | AA26: j
A27: 26 | B27: SignalGruppe | C27: 12.03.26 | D27: 02:01:00 | E27: CC_Master2 | F27: LINK | I27: 0 | L27: 0 | M27: 9,02 | T27: 13.03.26 | U27: 00:22:00 | W27: 0.93125 | X27: -101.5 | Y27: -52.8 | AA27: j
A28: 27 | B28: SignalGruppe | C28: 16.03.26 | D28: 12:21:00 | E28: cc_Master3 | F28: SOL | I28: 0 | L28: 0 | M28: 93,85 | T28: 17.03.26 | U28: 06:22:00 | W28: 0.75069444 | X28: -2.07 | Y28: -11.85 | AA28: j
A29: 28 | B29: Viona | C29: 17.03.26 | D29: 17:03:00 | E29: BitGet | F29: SOL | G29: s | I29: 0 | J29: 10 | L29: 0 | M29: 1,6347 | T29: 18.03.26 | U29: 12:06:00 | W29: 0.79375 | X29: 26.05 | Y29: 222.79 | AA29: j
A30: 29 | B30: Viona | C30: 20.03.26 | D30: 14:00:00 | E30: BitGet | F30: ORCA | I30: 0 | J30: 10 | L30: 0 | M30: 0,917 | T30: 21.03.26 | U30: 23:28:00 | W30: 1.375 | X30: 8.57 | Y30: 62.23 | AA30: j
A31: 30 | B31: Cornix | C31: 17.03.26 | E31: ByBit | F31: Versch | H31: 400 | I31: 0 | L31: 0 | M31: 385,7 | X31: -3.75 | Y31: -14.3 | AA31: j
A32: 31 | B32: Cornix | C32: 20.03.26 | E32: KuCoin | F32: Versch | H32: 398 | I32: 0 | L32: 0 | M32: 429 | X32: 7.8 | Y32: 30.13 | AA32: j
A33: 32 | B33: Cornix | E33: Binance | F33: Versch | H33: 394 | I33: 0 | L33: 0 | M33: 321 | X33: -18.53 | Y33: -126.7 | AA33: j
A34: 33 | B34: Viona | C34: 26.03.26 | E34: BitGet | F34: BAT | G34: s | H34: 3000 | I34: 750 | J34: 9 | K34: 25% | L34: 6750 | M34: 0,1041 | X34: 23.29 | Y34: 171.8 | AA34: j
A35: 34 | B35: Viona | C35: 27.03.26 | E35: BitGet | F35: DOGE | G35: l | H35: 3000 | I35: 900 | J35: 12 | K35: 30% | L35: 10800 | M35: 0,09002 | T35: 28.03.26 | U35: 12:39:00 | W35: 1.5 | X35: 36.94 | Y35: 327 | AA35: j
A36: 35 | B36: CK | C36: 29.03.26 | E36: CC_Master1 | F36: THX | G36: l | H36: 3000 | I36: 300 | J36: 10 | K36: 10% | L36: 3000 | M36: 0,32157 | T36: 29.03.26 | U36: 20:20:00 | W36: 0.84722222 | X36: -3.04 | Y36: -4.55 | AA36: j
A37: 36 | B37: MarkTrade | C37: 30.03.26 | E37: BitGet | F37: ETH | G37: l | H37: 3000 | I37: 480 | J37: 20 | K37: 16% | L37: 9600 | M37: 2071,11 | T37: 30.03.26 | U37: 21:32:00 | W37: 0.89722222 | X37: 7.89 | Y37: 105.21 | AA37: j
A38: 37 | B38: Viona | C38: 30.03.26 | E38: BitGet | F38: XMR | G38: s | H38: 3000 | I38: 900 | J38: 10 | K38: 30% | L38: 9000 | M38: 329,66 | T38: 30.03.26 | U38: 15:32:00 | W38: 0.64722222 | X38: 17.59 | Y38: 160.69 | AA38: j
A39: 38 | B39: Viona | C39: 30.03.26 | E39: BitGet | F39: RUNE | G39: s | H39: 3000 | I39: 660 | J39: 10 | K39: 22% | L39: 6600 | M39: 0,396 | T39: 31.03.26 | U39: 07:20:00 | W39: 1.2916667 | X39: -1.29 | Y39: -18.9 | AA39: j
A40: 39 | B40: Viona | C40: 31.03.26 | E40: BitGet | F40: DOGE | G40: l | H40: 3000 | I40: 810 | J40: 20 | K40: 27% | L40: 16200 | M40: 0,09041 | T40: 31.03.26 | U40: 09:45:00 | W40: 0.40625 | X40: 12.62 | Y40: 101.76 | AA40: j
...

Sheet Statistik
A1: TRADING STATISTIKEN 2026
A3: TRADE STATISTIKEN | H3: SIGNALGEBER STATISTIK
H4: Signalgeber | I4: Trades | J4: Wins | K4: Winrate | L4: PNL (USDT) | M4: ROI
A5: Gesamt Trades | B5: =COUNTA(Trades!A2:A2000) | H5: Viona | I5: =COUNTIF(Trades!B2:B2000,H5) | J5: =COUNTIFS(Trades!B2:B2000,H5,Trades!Y2:Y2000,">"&0) | K5: =IFERROR(J5/I5,"") | L5: =IFERROR(SUMIF(Trades!B$2:B$2000,H5,Trades!Y$2:Y$2000),"") | M5: =IFERROR(AVERAGEIF(Trades!B$2:B$2000,H5,Trades!X$2:X$2000),"")/100
A6: Wins | B6: =COUNTIFS(Trades!Y2:Y2000,">"&0,Trades!AA2:AA2000,"j") | H6: CK | I6: =COUNTIF(Trades!B2:B2000,H6) | J6: =COUNTIFS(Trades!B2:B2000,H6,Trades!Y2:Y2000,">"&0) | K6: =IFERROR(J6/I6,"") | L6: =IFERROR(SUMIF(Trades!B$2:B$2000,H6,Trades!Y$2:Y$2000),"") | M6: =IFERROR(AVERAGEIF(Trades!B$2:B$2000,H6,Trades!X$2:X$2000),"")/100
A7: Losses | B7: =COUNTIFS(Trades!Y2:Y2000,"<"&0,Trades!AA2:AA2000,"j") | H7: Global Crypto Research | I7: =COUNTIF(Trades!B2:B2000,H7) | J7: =COUNTIFS(Trades!B2:B2000,H7,Trades!Y2:Y2000,">"&0) | K7: =IFERROR(J7/I7,"") | L7: =IFERROR(SUMIF(Trades!B$2:B$2000,H7,Trades!Y$2:Y$2000),"") | M7: =IFERROR(AVERAGEIF(Trades!B$2:B$2000,H7,Trades!X$2:X$2000),"")/100
A8: Winrate | B8: =IFERROR(B6/B5,"") | H8: Crypto pro Traders | I8: =COUNTIF(Trades!B2:B2000,H8) | J8: =COUNTIFS(Trades!B2:B2000,H8,Trades!Y2:Y2000,">"&0) | K8: =IFERROR(J8/I8,"") | L8: =IFERROR(SUMIF(Trades!B$2:B$2000,H8,Trades!Y$2:Y$2000),"") | M8: =IFERROR(AVERAGEIF(Trades!B$2:B$2000,H8,Trades!X$2:X$2000),"")/100
A9: Gesamt PNL (USDT) | B9: =IFERROR(SUMIF(Trades!AA2:AA2000,"j",Trades!Y2:Y2000),0) | H9: Cornix | I9: =COUNTIF(Trades!B2:B2000,H9) | J9: =COUNTIFS(Trades!B2:B2000,H9,Trades!Y2:Y2000,">"&0) | K9: =IFERROR(J9/I9,"") | L9: =IFERROR(SUMIF(Trades!B$2:B$2000,H9,Trades!Y$2:Y$2000),"") | M9: =IFERROR(AVERAGEIF(Trades!B$2:B$2000,H9,Trades!X$2:X$2000),"")/100
A10: Ø Trade-Dauer | B10: =IFERROR(AVERAGEIF(Trades!W2:W2000,">"&0),0) | H10: CryptoCult | I10: =COUNTIF(Trades!B2:B2000,H10) | J10: =COUNTIFS(Trades!B2:B2000,H10,Trades!Y2:Y2000,">"&0) | K10: =IFERROR(J10/I10,"") | L10: =IFERROR(SUMIF(Trades!B$2:B$2000,H10,Trades!Y$2:Y$2000),"") | M10: =IFERROR(AVERAGEIF(Trades!B$2:B$2000,H10,Trades!X$2:X$2000),"")/100
A12: EINZAHLUNGEN
A13: Datum | B13: Summe (USDT) | C13: Initialen | D13: Binance | E13: Bybit | F13: Toobit | G13: KuCoin | H13: Bitget | I13: Phemex | J13: Wallet Trust
A14: 17.02.2026 | B14: 1000 | C14: TR | I14: 1000 | J14: 2
A15: 07.03.2026 | B15: 3700 | C15: TR | H15: 3700
A16: 10.04.2026 | B16: 5300 | C16: TR | H16: 5300
A17: 10.04.2026 | B17: 10000 | C17: GT | H17: 9000 | I17: 1000
A20: TOTAL Einzahlungen | B20: 20000 | C20: =SUM(C14:C19) | D20: =SUM(D14:D19) | E20: =SUM(E14:E19) | F20: =SUM(F14:F19) | G20: =SUM(G14:G19) | H20: =SUM(H14:H19) | I20: =SUM(I14:I19) | J20: =SUM(J14:J19)
A23: KONTOSTAND PRO BÖRSE
A24: Bitget | E24: Phemex | I24: Binance
A25: Datum | B25: Betrag (USDT) | C25: Notiz | E25: Datum | F25: Betrag (USDT) | G25: Notiz | I25: Datum | J25: Betrag (USDT) | K25: Notiz
A26: 46126 | B26: 19542.19 | E26: 46126 | F26: 2067.06 | J26: 0
A27: 46128 | B27: 20552.66 | E27: 46128 | F27: 2015.73 | G27: 35 zu Toolbit
A28: 46138 | B28: 20310 | E28: 46138 | F28: 2010
A35: Bybit | E35: Toobit | I35: Kucoin
A36: Datum | B36: Betrag (USDT) | C36: Notiz | E36: Datum | F36: Betrag (USDT) | G36: Notiz | I36: Datum | J36: Betrag (USDT) | K36: Notiz
B37: 0 | E37: 46127 | F37: 34 | G37: von Phemex | J37: 0
E38: 46128 | F38: 37.25
E39: 46128 | F39: 37.25
A51: AUSZAHLUNGEN & GEWINNVERTEILUNG
A52: Übersicht (ab 17.02.2026)
A53: Zeitraum / Datum | B53: Brutto | C53: Ausgaben | D53: Netto | E53: TR (50%) | F53: GT (50%) | G53: CK (50%)
A54: 17.02–31.03.2026 | B54: 1090 | D54: =B54-C54 | E54: =D54*0.5 | G54: =D54*0.5
A55: 07.04.2026 | B55: 866 | D55: =B55-C55 | E55: =D55*0.5 | G55: =D55*0.5
A56: 09.04.2026 | B56: 426 | D56: =B56-C56 | E56: =D56*0.5 | G56: =D56*0.5
A57: 46138 | B57: 2350 | C57: 100 | D57: =IF(B57="","",B57-C57) | E57: =IF(D57="","",D57*0.25) | F57: =D57*0.25 | G57: =IF(D57="","",D57*0.5)
B58: 0 | D58: =IF(B58="","",B58-C58) | E58: =IF(D58="","",D58*0.25) | F58: =D58*0.25 | G58: =IF(D58="","",D58*0.5)
B59: 0 | D59: =IF(B59="","",B59-C59) | E59: =IF(D59="","",D59*0.25) | F59: =D59*0.25 | G59: =IF(D59="","",D59*0.5)
B60: 0 | D60: =IF(B60="","",B60-C60) | E60: =IF(D60="","",D60*0.25) | F60: =D60*0.25 | G60: =IF(D60="","",D60*0.5)
B61: 0 | D61: =IF(B61="","",B61-C61) | E61: =IF(D61="","",D61*0.25) | F61: =D61*0.25 | G61: =IF(D61="","",D61*0.5)
B62: 0 | D62: =IF(B62="","",B62-C62) | E62: =IF(D62="","",D62*0.25) | F62: =D62*0.25 | G62: =IF(D62="","",D62*0.5)
B63: 0 | D63: =IF(B63="","",B63-C63) | E63: =IF(D63="","",D63*0.25) | F63: =D63*0.25 | G63: =IF(D63="","",D63*0.5)
...

Sheet KODA-Bot
A1: # | B1: Datum | C1: Zeit | D1: Coin | E1: Richtung | F1: Strategie | G1: Entry | H1: TP1 (50%) | I1: TP1 Kurs | J1: SL | K1: SL Kurs | L1: Rest Exit | M1: Rest Kurs | N1: ROI % | O1: PNL USDT | P1: Net PNL | Q1: Dauer | R1: Status | S1: EE Main | T1: EE Signal | U1: Steilheit % | V1: Golden Wick | W1: Notiz
A2: 1 | B2: 2026-05-04 | C2: 10:00 | D2: BTC | E2: LONG | F2: ER1 | G2: 76500 | H2: +1.0% | I2: 77265 | J2: -1.2% | K2: 75582 | L2: Trailing | M2: 77800 | N2: 1.7 | O2: 1.7 | P2: 1.54 | Q2: 2.5h | R2: TESTNET | S2: 3.42 | T2: 2.15 | U2: 1.8 | V2: Nein | W2: Erster Testnet-Trade
